Workbook

Sheet Chart Summary

Sheet PF, THD, EFF
A2: EFFICIENCY, PF, and THD
A3: DER-925 Unit 7
B6: WITH DAUGHTER BOARD | AE6: NO DAUGHTER BOARD
B9: LOAD: 48V LED Load | AE9: LOAD: 48V LED Load
B10: Input | D10: Input Measurement | I10: Output 1 Measurement | N10: Remarks | AE10: Input | AG10: Input Measurement | AL10: Output 1 Measurement | AQ10: Remarks
B11: Vac (rms) | C11: Freq (Hz) | D11: Vin (rms) | E11: Iin (mA) | F11: Pin (W) | G11: PF | H11: % THD | I11: Vo (V) | J11: Io (mA) | K11: Po (W) | L11: %V Reg | M11: Efficiency | AE11: Vac (rms) | AF11: Freq (Hz) | AG11: Vin (rms) | AH11: Iin (mA) | AI11: Pin (W) | AJ11: PF | AK11: % THD | AL11: Vo (V) | AM11: Io (mA) | AN11: Po (W) | AO11: %V Reg | AP11: Efficiency
B12: 90 | C12: 60 | D12: 89.85 | E12: 470.09 | F12: 41.974 | G12: 0.9938 | H12: 6.941 | I12: 47.814 | J12: 767.2 | K12: 36.653 | L12: -1.6410256 | M12: 87.323105
B13: 100 | C13: 60 | D13: 99.89 | E13: 419.2 | F13: 41.668 | G13: 0.9951 | H13: 4.253 | I13: 47.815 | J13: 767.4 | K13: 36.661 | L13: -1.6153846 | M13: 87.983585
B14: 110 | C14: 60 | D14: 109.93 | E14: 379.74 | F14: 41.497 | G14: 0.9941 | H14: 3.748 | I14: 47.815 | J14: 767.5 | K14: 36.666 | L14: -1.6025641 | M14: 88.358195
B15: 115 | C15: 60 | D15: 114.9 | E15: 363.33 | F15: 41.443 | G15: 0.9927 | H15: 3.905 | I15: 47.815 | J15: 767.7 | K15: 36.675 | L15: -1.5769231 | M15: 88.495041
B16: 120 | C16: 60 | D16: 119.88 | E16: 348.33 | F16: 41.41 | G16: 0.9917 | H16: 4.139 | I16: 47.816 | J16: 767.8 | K16: 36.681 | L16: -1.5641026 | M16: 88.580053
B17: 132 | C17: 60 | D17: 131.87 | E17: 316.41 | F17: 41.272 | G17: 0.9891 | H17: 3.791 | I17: 47.816 | J17: 767.8 | K17: 36.681 | L17: -1.5641026 | M17: 88.876236
B18: 180 | C18: 50 | D18: 179.87 | E18: 233.7 | F18: 41.073 | G18: 0.9771 | H18: 5.289 | I18: 47.815 | J18: 767.9 | K18: 36.682 | L18: -1.5512821 | M18: 89.309279
B19: 200 | C19: 50 | D19: 199.93 | E19: 211.86 | F19: 41.06 | G19: 0.9693 | H19: 6.204 | I19: 47.815 | J19: 768.1 | K19: 36.691 | L19: -1.525641 | M19: 89.359474
B20: 230 | C20: 50 | D20: 229.92 | E20: 187.34 | F20: 41.07 | G20: 0.9536 | H20: 7.027 | I20: 47.815 | J20: 768.2 | K20: 36.699 | L20: -1.5128205 | M20: 89.357195
B21: 265 | C21: 50 | D21: 264.91 | E21: 167.05 | F21: 41.13 | G21: 0.9294 | H21: 8.349 | I21: 47.816 | J21: 768.2 | K21: 36.7 | L21: -1.5128205 | M21: 89.229273
B22: 277 | C22: 60 | D22: 276.94 | E22: 164.77 | F22: 41.16 | G22: 0.902 | H22: 9.909 | I22: 47.818 | J22: 768.5 | K22: 36.714 | L22: -1.474359 | M22: 89.198251
B23: 300 | C23: 60 | D23: 300 | E23: 156.61 | F23: 41.22 | G23: 0.8773 | H23: 11.094 | I23: 47.818 | J23: 768.5 | K23: 36.716 | L23: -1.474359 | M23: 89.073265
B25: LOAD: 36V LED Load | AE25: LOAD: 36V LED Load
B26: Input | D26: Input Measurement | I26: Output 1 Measurement | N26: Remarks | AE26: Input | AG26: Input Measurement | AL26: Output 1 Measurement | AQ26: Remarks
B27: Vac (rms) | C27: Freq (Hz) | D27: Vin (rms) | E27: Iin (mA) | F27: Pin (W) | G27: PF | H27: % THD | I27: Vo (V) | J27: Io (mA) | K27: Po (W) | L27: %V Reg | M27: Efficiency | AE27: Vac (rms) | AF27: Freq (Hz) | AG27: Vin (rms) | AH27: Iin (mA) | AI27: Pin (W) | AJ27: PF | AK27: % THD | AL27: Vo (V) | AM27: Io (mA) | AN27: Po (W) | AO27: %V Reg | AP27: Efficiency
B28: 90 | C28: 60 | D28: 89.89 | E28: 355.28 | F28: 31.758 | G28: 0.9944 | H28: 3.997 | I28: 36.186 | J28: 767.9 | K28: 27.763 | L28: -1.5512821 | M28: 87.420492
B29: 100 | C29: 60 | D29: 99.92 | E29: 318.69 | F29: 31.604 | G29: 0.9924 | H29: 4.217 | I29: 36.183 | J29: 767.7 | K29: 27.753 | L29: -1.5769231 | M29: 87.814834
B30: 110 | C30: 60 | D30: 109.96 | E30: 289.31 | F30: 31.499 | G30: 0.9902 | H30: 3.832 | I30: 36.182 | J30: 767.8 | K30: 27.755 | L30: -1.5641026 | M30: 88.113908
B31: 115 | C31: 60 | D31: 114.93 | E31: 276.78 | F31: 31.463 | G31: 0.989 | H31: 4.071 | I31: 36.182 | J31: 767.9 | K31: 27.756 | L31: -1.5512821 | M31: 88.217907
B32: 120 | C32: 60 | D32: 119.91 | E32: 265.7 | F32: 31.447 | G32: 0.9871 | H32: 3.97 | I32: 36.183 | J32: 768.1 | K32: 27.765 | L32: -1.525641 | M32: 88.291411
B33: 132 | C33: 60 | D33: 131.9 | E33: 241.99 | F33: 31.378 | G33: 0.9831 | H33: 4.14 | I33: 36.183 | J33: 768 | K33: 27.764 | L33: -1.5384615 | M33: 88.482376
B34: 180 | C34: 50 | D34: 179.89 | E34: 179.87 | F34: 31.206 | G34: 0.9645 | H34: 6.055 | I34: 36.175 | J34: 766.4 | K34: 27.697 | L34: -1.7435897 | M34: 88.755368
B35: 200 | C35: 50 | D35: 199.95 | E35: 164 | F35: 31.22 | G35: 0.952 | H35: 7.214 | I35: 36.176 | J35: 766.6 | K35: 27.704 | L35: -1.7179487 | M35: 88.737988
B36: 230 | C36: 50 | D36: 229.87 | E36: 146.45 | F36: 31.259 | G36: 0.9286 | H36: 7.952 | I36: 36.177 | J36: 766.7 | K36: 27.71 | L36: -1.7051282 | M36: 88.64647
B37: 265 | C37: 50 | D37: 264.87 | E37: 132.45 | F37: 31.336 | G37: 0.8933 | H37: 10.015 | I37: 36.177 | J37: 766.8 | K37: 27.713 | L37: -1.6923077 | M37: 88.438218
B38: 277 | C38: 60 | D38: 276.89 | E38: 132.84 | F38: 31.445 | G38: 0.8549 | H38: 11.668 | I38: 36.186 | J38: 768.5 | K38: 27.782 | L38: -1.474359 | M38: 88.351089
B39: 300 | C39: 60 | D39: 299.96 | E39: 127.75 | F39: 31.51 | G39: 0.8222 | H39: 13.393 | I39: 36.186 | J39: 768.4 | K39: 27.78 | L39: -1.4871795 | M39: 88.162488
B41: LOAD: 24V LED Load | AE41: LOAD: 24V LED Load
B42: Input | D42: Input Measurement | I42: Output 1 Measurement | N42: Remarks | AE42: Input | AG42: Input Measurement | AL42: Output 1 Measurement | AQ42: Remarks
B43: Vac (rms) | C43: Freq (Hz) | D43: Vin (rms) | E43: Iin (mA) | F43: Pin (W) | G43: PF | H43: % THD | I43: Vo (V) | J43: Io (mA) | K43: Po (W) | L43: %V Reg | M43: Efficiency | AE43: Vac (rms) | AF43: Freq (Hz) | AG43: Vin (rms) | AH43: Iin (mA) | AI43: Pin (W) | AJ43: PF | AK43: % THD | AL43: Vo (V) | AM43: Io (mA) | AN43: Po (W) | AO43: %V Reg | AP43: Efficiency
B44: 90 | C44: 60 | D44: 89.79 | E44: 238.8 | F44: 21.185 | G44: 0.9881 | H44: 5.747 | I44: 23.855 | J44: 767.7 | K44: 18.295 | L44: -1.5769231 | M44: 86.358272
B45: 100 | C45: 60 | D45: 99.83 | E45: 214.45 | F45: 21.112 | G45: 0.986 | H45: 4.52 | I45: 23.855 | J45: 768.1 | K45: 18.304 | L45: -1.525641 | M45: 86.699507
B46: 110 | C46: 60 | D46: 109.88 | E46: 195.31 | F46: 21.064 | G46: 0.9815 | H46: 4.85 | I46: 23.855 | J46: 767.9 | K46: 18.3 | L46: -1.5512821 | M46: 86.878086
B47: 115 | C47: 60 | D47: 114.85 | E47: 187.34 | F47: 21.056 | G47: 0.9786 | H47: 5.186 | I47: 23.854 | J47: 767.9 | K47: 18.3 | L47: -1.5512821 | M47: 86.911094
...

Sheet Harmonics
A4: Current Harmonics
A5: ='PF, THD, EFF'!A3:H3
B8: HARMONICS: 120 VAC, 48V LED Load | AA8: HARMONICS: 120 VAC, 36V LED Load | AZ8: HARMONICS: 120 VAC, 24V LED Load
B11: 120 | C11: 60 | D11: 119.88 | E11: 348.3 | F11: 41.404 | G11: 0.9916 | H11: 4.114 | I11: 47.819 | J11: 767.9 | K11: 36.684 | L11: -1.5512821 | M11: 88.600135 | AA11: 120 | AB11: 60 | AC11: 119.91 | AD11: 265.88 | AE11: 31.469 | AF11: 0.9871 | AG11: 3.951 | AH11: 36.19 | AI11: 768.3 | AJ11: 27.78 | AK11: -1.5 | AL11: 88.277352 | AZ11: 277 | BA11: 60 | BB11: 276.92 | BC11: 100.4 | BD11: 21.26 | BE11: 0.7647 | BF11: 17.421 | BG11: 23.856 | BH11: 768.5 | BI11: 18.315 | BJ11: -1.474359 | BK11: 86.147695
B14: nth order | C14: mA content | D14: % content | E14: mA Limit <25W | F14: % limit, >25W | G14: Remarks | AA14: nth order | AB14: mA content | AC14: % content | AD14: mA Limit <25W | AE14: % limit, >25W | AF14: Remarks | AZ14: nth order | BA14: mA content | BB14: % content | BC14: mA Limit <25W | BD14: % limit, >25W | BE14: Remarks
B15: 1 | C15: 347.09 | AA15: 1 | AB15: 265.1 | AZ15: 1 | BA15: 97.23
B16: 2 | C16: 0.11 | D16: 0.031692068 | F16: 2 | G16: pass | AA16: 2 | AB16: 0.23 | AC16: 0.086759713 | AE16: 2 | AF16: pass | AZ16: 2 | BA16: 0.06 | BB16: 0.061709349 | BD16: 2
B17: 3 | C17: 11.57 | D17: 3.3334294 | E17: 140.7736 | F17: 29.747999 | G17: pass | AA17: 3 | AB17: 8.56 | AC17: 3.2289702 | AD17: 106.9946 | AE17: 29.613001 | AF17: pass | AZ17: 3 | BA17: 12.45 | BB17: 12.80469 | BC17: 72.284 | BD17: 22.941 | BE17: pass
B18: 5 | C18: 1.04 | D18: 0.2996341 | E18: 78.6676 | F18: 10 | G18: pass | AA18: 5 | AB18: 0.46 | AC18: 0.17351943 | AD18: 59.7911 | AE18: 10 | AF18: pass | AZ18: 5 | BA18: 6.81 | BB18: 7.0040111 | BC18: 40.394 | BD18: 10 | BE18: pass
B19: 7 | C19: 3.17 | D19: 0.91330779 | E19: 41.404 | F19: 7 | G19: pass | AA19: 7 | AB19: 2.48 | AC19: 0.93549604 | AD19: 31.469 | AE19: 7 | AF19: pass | AZ19: 7 | BA19: 4.52 | BB19: 4.648771 | BC19: 21.26 | BD19: 7 | BE19: pass
B20: 9 | C20: 0.07 | D20: 0.02016768 | E20: 20.702 | F20: 5 | G20: pass | AA20: 9 | AB20: 0.58 | AC20: 0.21878536 | AD20: 15.7345 | AE20: 5 | AF20: pass | AZ20: 9 | BA20: 3.5 | BB20: 3.599712 | BC20: 10.63 | BD20: 5 | BE20: pass
B21: 11 | C21: 1.57 | D21: 0.45233225 | E21: 14.4914 | F21: 3 | G21: pass | AA21: 11 | AB21: 1.93 | AC21: 0.72802716 | AD21: 11.01415 | AE21: 3 | AF21: pass | AZ21: 11 | BA21: 3.05 | BB21: 3.1368919 | BC21: 7.441 | BD21: 3 | BE21: pass
B22: 13 | C22: 2.21 | D22: 0.63672246 | E22: 12.261954 | F22: 3 | G22: pass | AA22: 13 | AB22: 1.32 | AC22: 0.49792531 | AD22: 9.3196654 | AE22: 3 | AF22: pass | AZ22: 13 | BA22: 1.67 | BB22: 1.7175769 | BC22: 6.2962308 | BD22: 3 | BE22: pass
B23: 15 | C23: 1.95 | D23: 0.56181394 | E23: 10.627027 | F23: 3 | G23: pass | AA23: 15 | AB23: 0.85 | AC23: 0.32063372 | AD23: 8.0770433 | AE23: 3 | AF23: pass | AZ23: 15 | BA23: 2.19 | BB23: 2.2523912 | BC23: 5.4567333 | BD23: 3 | BE23: pass
B24: 17 | C24: 1.99 | D24: 0.57333833 | E24: 9.3767882 | F24: 3 | G24: pass | AA24: 17 | AB24: 1.02 | AC24: 0.38476047 | AD24: 7.1268029 | AE24: 3 | AF24: pass | AZ24: 17 | BA24: 1.85 | BB24: 1.9027049 | BC24: 4.8147647 | BD24: 3 | BE24: pass
B25: 19 | C25: 4.26 | D25: 1.2273474 | E25: 8.3897579 | F25: 3 | G25: pass | AA25: 19 | AB25: 0.78 | AC25: 0.29422859 | AD25: 6.3766132 | AE25: 3 | AF25: pass | AZ25: 19 | BA25: 1.74 | BB25: 1.7895711 | BC25: 4.3079474 | BD25: 3 | BE25: pass
B26: 21 | C26: 1.46 | D26: 0.42064018 | E26: 7.5907333 | F26: 3 | G26: pass | AA26: 21 | AB26: 0.72 | AC26: 0.27159562 | AD26: 5.7693167 | AE26: 3 | AF26: pass | AZ26: 21 | BA26: 0.73 | BB26: 0.75079708 | BC26: 3.8976667 | BD26: 3 | BE26: pass
B27: 23 | C27: 3.52 | D27: 1.0141462 | E27: 6.9306696 | F27: 3 | G27: pass | AA27: 23 | AB27: 2.75 | AC27: 1.0373444 | AD27: 5.267637 | AE27: 3 | AF27: pass | AZ27: 23 | BA27: 1.91 | BB27: 1.9644143 | BC27: 3.5587391 | BD27: 3 | BE27: pass
B28: 25 | C28: 0.52 | D28: 0.14981705 | E28: 6.376216 | F28: 3 | G28: pass | AA28: 25 | AB28: 1.69 | AC28: 0.63749528 | AD28: 4.846226 | AE28: 3 | AF28: pass | AZ28: 25 | BA28: 1.23 | BB28: 1.2650417 | BC28: 3.27404 | BD28: 3 | BE28: pass
... B36: 41 | C36: 0.54 | D36: 0.15557924 | E36: 3.8879366 | F36: 3 | G36: pass | AA36: 41 | AB36: 0.31 | AC36: 0.116937 | AD36: 2.9550159 | AE36: 3 | AF36: pass | AZ36: 41 | BA36: 1.56 | BB36: 1.6044431 | BC36: 1.9963659 | BD36: 3 | BE36: pass
B39: HARMONICS: 230 VAC, 48V LED Load | AA39: HARMONICS: 230 VAC, 36V LED Load | AZ39: HARMONICS: 230 VAC, 24V LED Load
B42: 230 | C42: 50 | D42: 229.85 | E42: 187.32 | F42: 41.067 | G42: 0.9538 | H42: 6.699 | I42: 47.819 | J42: 768.4 | K42: 36.708 | L42: -1.4871795 | M42: 89.385638 | AA42: 230 | AB42: 50 | AC42: 229.88 | AD42: 145.34 | AE42: 31 | AF42: 0.9278 | AG42: 8.314 | AH42: 36.172 | AI42: 765.9 | AJ42: 27.678 | AK42: -1.8076923 | AL42: 89.283871 | AZ42: 230 | BA42: 50 | BB42: 229.9 | BC42: 105.51 | BD42: 21.113 | BE42: 0.8704 | BF42: 12.203 | BG42: 23.854 | BH42: 767.1 | BI42: 18.28 | BJ42: -1.6538462 | BK42: 86.581727
B45: nth order | C45: mA content | D45: % content | E45: mA Limit <25W | F45: % limit, >25W | G45: Remarks | AA45: nth order | AB45: mA content | AC45: % content | AD45: mA Limit <25W | AE45: % limit, >25W | AF45: Remarks | AZ45: nth order | BA45: mA content | BB45: % content | BC45: mA Limit <25W | BD45: % limit, >25W | BE45: Remarks
B46: 1 | C46: 185.69 | AA46: 1 | AB46: 143.84 | AZ46: 1 | BA46: 103.08
B47: 2 | C47: 0.32 | D47: 0.17233023 | F47: 2 | G47: pass | AA47: 2 | AB47: 0.15 | AC47: 0.10428254 | AE47: 2 | AF47: pass | AZ47: 2 | BA47: 0.17 | BB47: 0.16492045 | BD47: 2
B48: 3 | C48: 11.39 | D48: 6.133879 | E48: 139.6278 | F48: 28.614 | G48: pass | AA48: 3 | AB48: 10.14 | AC48: 7.0494994 | AD48: 105.4 | AE48: 27.834 | AF48: pass | AZ48: 3 | BA48: 10.73 | BB48: 10.409391 | BC48: 71.7842 | BD48: 26.112 | BE48: pass
B49: 5 | C49: 1.57 | D49: 0.84549518 | E49: 78.0273 | F49: 10 | G49: pass | AA49: 5 | AB49: 1.87 | AC49: 1.3000556 | AD49: 58.9 | AE49: 10 | AF49: pass | AZ49: 5 | BA49: 3.14 | BB49: 3.0461777 | BC49: 40.1147 | BD49: 10 | BE49: pass
B50: 7 | C50: 1.99 | D50: 1.0716786 | E50: 41.067 | F50: 7 | G50: pass | AA50: 7 | AB50: 2.13 | AC50: 1.480812 | AD50: 31 | AE50: 7 | AF50: pass | AZ50: 7 | BA50: 2.48 | BB50: 2.4058983 | BC50: 21.113 | BD50: 7 | BE50: pass
B51: 9 | C51: 1.95 | D51: 1.0501373 | E51: 20.5335 | F51: 5 | G51: pass | AA51: 9 | AB51: 2.04 | AC51: 1.4182425 | AD51: 15.5 | AE51: 5 | AF51: pass | AZ51: 9 | BA51: 2.74 | BB51: 2.6581296 | BC51: 10.5565 | BD51: 5 | BE51: pass
B52: 11 | C52: 1.8 | D52: 0.96935753 | E52: 14.37345 | F52: 3 | G52: pass | AA52: 11 | AB52: 1.78 | AC52: 1.2374861 | AD52: 10.85 | AE52: 3 | AF52: pass | AZ52: 11 | BA52: 2.08 | BB52: 2.0178502 | BC52: 7.38955 | BD52: 3 | BE52: pass
B53: 13 | C53: 1.16 | D53: 0.62469708 | E53: 12.16215 | F53: 3 | G53: pass | AA53: 13 | AB53: 1.71 | AC53: 1.1888209 | AD53: 9.1807692 | AE53: 3 | AF53: pass | AZ53: 13 | BA53: 1.92 | BB53: 1.862631 | BC53: 6.2526962 | BD53: 3 | BE53: pass
B54: 15 | C54: 1.58 | D54: 0.8508805 | E54: 10.54053 | F54: 3 | G54: pass | AA54: 15 | AB54: 1.74 | AC54: 1.2096774 | AD54: 7.9566667 | AE54: 3 | AF54: pass | AZ54: 15 | BA54: 1.37 | BB54: 1.3290648 | BC54: 5.4190033 | BD54: 3 | BE54: pass
B55: 17 | C55: 1.38 | D55: 0.74317411 | E55: 9.3004676 | F55: 3 | G55: pass | AA55: 17 | AB55: 1.49 | AC55: 1.0358732 | AD55: 7.0205882 | AE55: 3 | AF55: pass | AZ55: 17 | BA55: 1.4 | BB55: 1.3581684 | BC55: 4.7814735 | BD55: 3 | BE55: pass
B56: 19 | C56: 1.06 | D56: 0.57084388 | E56: 8.3214711 | F56: 3 | G56: pass | AA56: 19 | AB56: 1.3 | AC56: 0.90378198 | AD56: 6.2815789 | AE56: 3 | AF56: pass | AZ56: 19 | BA56: 1.01 | BB56: 0.9798215 | BC56: 4.2781605 | BD56: 3 | BE56: pass
B57: 21 | C57: 1.5 | D57: 0.80779794 | E57: 7.52895 | F57: 3 | G57: pass | AA57: 21 | AB57: 1.14 | AC57: 0.79254727 | AD57: 5.6833333 | AE57: 3 | AF57: pass | AZ57: 21 | BA57: 0.89 | BB57: 0.86340706 | BC57: 3.8707167 | BD57: 3 | BE57: pass
B58: 23 | C58: 1.22 | D58: 0.65700899 | E58: 6.8742587 | F58: 3 | G58: pass | AA58: 23 | AB58: 1.02 | AC58: 0.70912125 | AD58: 5.1891304 | AE58: 3 | AF58: pass | AZ58: 23 | BA58: 0.88 | BB58: 0.85370586 | BC58: 3.5341326 | BD58: 3 | BE58: pass
B59: 25 | C59: 1.23 | D59: 0.66239431 | E59: 6.324318 | F59: 3 | G59: pass | AA59: 25 | AB59: 0.67 | AC59: 0.46579533 | AD59: 4.774 | AE59: 3 | AF59: pass | AZ59: 25 | BA59: 0.82 | BB59: 0.79549864 | BC59: 3.251402 | BD59: 3 | BE59: pass
... B67: 41 | C67: 0.39 | D67: 0.21002747 | E67: 3.8562915 | F67: 3 | G67: pass | AA67: 41 | AB67: 0.47 | AC67: 0.32675195 | AD67: 2.9109756 | AE67: 3 | AF67: pass | AZ67: 41 | BA67: 0.41 | BB67: 0.39774932 | BC67: 1.9825622 | BD67: 3 | BE67: pass
B70: HARMONICS: 277 VAC, 48V LED Load | AA70: HARMONICS: 277 VAC, 36V LED Load | AZ70: HARMONICS: 277 VAC, 24V LED Load
B73: 277 | C73: 60 | D73: 276.87 | E73: 164.76 | F73: 41.166 | G73: 0.9024 | H73: 8.998 | I73: 47.826 | J73: 768.9 | K73: 36.74 | L73: -1.4230769 | M73: 89.248409 | AA73: 230 | AB73: 50 | AC73: 229.88 | AD73: 146.59 | AE73: 31.287 | AF73: 0.9285 | AG73: 8.005 | AH73: 36.183 | AI73: 767.2 | AJ73: 27.731 | AK73: -1.6410256 | AL73: 88.634257 | AZ73: 277 | BA73: 60 | BB73: 276.94 | BC73: 99.21 | BD73: 20.968 | BE73: 0.7632 | BF73: 17.067 | BG73: 23.913 | BH73: 766.5 | BI73: 18.31 | BJ73: -1.7307692 | BK73: 87.323541
...

Sheet No Load Input Power
A2: No Load Input Power
A3: ='PF, THD, EFF'!A3:H3
B7: NO LOAD INPUT POWER
B8: Input | D8: Input Measurement | I8: Output 1 Measurement
B9: Vac (rms) | C9: Freq (Hz) | D9: Vin (rms) | E9: Iin (mA) | F9: Pin (W) | G9: PF | H9: % THD | I9: Vo (V) | J9: Io (mA) | K9: Po (W) | L9: %I Reg | M9: Efficiency
B10: 90 | C10: 60 | D10: 89.94 | E10: 24.959 | F10: 0.4191 | G10: 0.1871 | I10: 52.324 | J10: 0 | K10: 0 | L10: -100 | M10: 0
B11: 100 | C11: 60 | D11: 99.97 | E11: 25.797 | F11: 0.50874 | G11: 0.1976 | I11: 52.322 | J11: 0 | K11: 0 | L11: -100 | M11: 0
B12: 110 | C12: 60 | D12: 110 | E12: 25.88 | F12: 0.50004 | G12: 0.178 | I12: 52.316 | J12: 0 | K12: 0 | L12: -100 | M12: 0
B13: 115 | C13: 60 | D13: 114.97 | E13: 25.801 | F13: 0.47196 | G13: 0.1586 | I13: 52.308 | J13: 0 | K13: 0 | L13: -100 | M13: 0
B14: 120 | C14: 60 | D14: 119.94 | E14: 25.88 | F14: 0.45198 | G14: 0.1469 | I14: 52.302 | J14: 0 | K14: 1e-05 | L14: -100 | M14: 0.0022124873
B15: 132 | C15: 60 | D15: 131.93 | E15: 26.088 | F15: 0.41772 | G15: 0.1213 | I15: 52.297 | J15: 0 | K15: 1e-05 | L15: -100 | M15: 0.0023939481
B16: 180 | C16: 50 | D16: 179.91 | E16: 25.793 | F16: 0.35973 | G16: 0.0774 | I16: 52.288 | J16: 0 | K16: 2e-05 | L16: -100 | M16: 0.0055597253
B17: 200 | C17: 50 | D17: 199.97 | E17: 26.439 | F17: 0.34983 | G17: 0.0653 | I17: 52.285 | J17: 0 | K17: 1e-05 | L17: -100 | M17: 0.0028585313
B18: 230 | C18: 50 | D18: 229.96 | E18: 27.875 | F18: 0.34308 | G18: 0.0549 | I18: 52.281 | J18: 0 | K18: 1e-05 | L18: -100 | M18: 0.0029147721
B19: 265 | C19: 50 | D19: 264.95 | E19: 29.811 | F19: 0.34332 | G19: 0.043 | I19: 52.277 | J19: 0 | K19: 1e-05 | L19: -100 | M19: 0.0029127345
B20: 277 | C20: 60 | D20: 276.98 | E20: 34.678 | F20: 0.34635 | G20: 0.0368 | I20: 52.275 | J20: 0 | K20: 1e-05 | L20: -100 | M20: 0.0028872528
B21: 300 | C21: 60 | D21: 300.04 | E21: 36.43 | F21: 0.35361 | G21: 0.031 | I21: 52.273 | J21: 0 | K21: 1e-05 | L21: -100 | M21: 0.0028279743
B25: LIGHT OFF INPUT POWER
B26: Input | D26: Input Measurement | I26: Output 1 Measurement
B27: Vac (rms) | C27: Freq (Hz) | D27: Vin (rms) | E27: Iin (mA) | F27: Pin (W) | G27: PF | H27: % THD | I27: Vo (V) | J27: Io (mA) | K27: Po (W) | L27: %I Reg | M27: Efficiency
B28: 90 | C28: 60 | D28: 89.94 | E28: 22.972 | F28: 0.056661 | G28: 0.0279 | I28: 17.346 | J28: 0 | K28: 0 | L28: -100 | M28: 0
B29: 100 | C29: 60 | D29: 99.97 | E29: 23.412 | F29: 0.058701 | G29: 0.025 | I29: 17.339 | J29: 0 | K29: 0 | L29: -100 | M29: 0
B30: 110 | C30: 60 | D30: 110 | E30: 23.839 | F30: 0.061401 | G30: 0.0224 | I30: 17.338 | J30: 0 | K30: 0 | L30: -100 | M30: 0
B31: 115 | C31: 60 | D31: 114.97 | E31: 24.063 | F31: 0.063516 | G31: 0.0245 | I31: 17.338 | J31: 0 | K31: 0 | L31: -100 | M31: 0
B32: 120 | C32: 60 | D32: 119.94 | E32: 24.266 | F32: 0.066054 | G32: 0.0224 | I32: 17.338 | J32: 0 | K32: 0 | L32: -100 | M32: 0
B33: 132 | C33: 60 | D33: 131.93 | E33: 24.801 | F33: 0.073365 | G33: 0.0215 | I33: 17.338 | J33: 0 | K33: 0 | L33: -100 | M33: 0
B34: 180 | C34: 50 | D34: 179.91 | E34: 25.049 | F34: 0.110325 | G34: 0.0254 | I34: 17.335 | J34: 0 | K34: 0 | L34: -100 | M34: 0
B35: 200 | C35: 50 | D35: 199.97 | E35: 25.845 | F35: 0.127824 | G35: 0.0247 | I35: 17.333 | J35: 0 | K35: 0 | L35: -100 | M35: 0
B36: 230 | C36: 50 | D36: 229.96 | E36: 27.4 | F36: 0.155469 | G36: 0.0246 | I36: 17.334 | J36: 0 | K36: 0 | L36: -100 | M36: 0
B37: 265 | C37: 50 | D37: 264.95 | E37: 29.558 | F37: 0.190854 | G37: 0.0245 | I37: 17.327 | J37: 0 | K37: 0 | L37: -100 | M37: 0
B38: 277 | C38: 60 | D38: 276.97 | E38: 34.417 | F38: 0.204924 | G38: 0.0217 | I38: 17.326 | J38: 0 | K38: 0 | L38: -100 | M38: 0
B39: 300 | C39: 60 | D39: 300.04 | E39: 36.25 | F39: 0.231006 | G39: 0.0213 | I39: 17.323 | J39: 0 | K39: 1e-05 | L39: -100 | M39: 0.0043288919

Sheet Analog Dimming
A2: Legacy Dimming: Analog
A3: ='PF, THD, EFF'!A3:H3
B8: 48V LED, 120 VAC | Q8: 48V LED, 230 VAC | AF8: 48V LED, 277 VAC | AV8: 36V LED, 120 VAC | BK8: 36V LED, 230 VAC | BZ8: 36V LED, 277 VAC | CP8: 24V LED, 120 VAC | DE8: 24V LED, 230 VAC | DT8: 24V LED, 277 VAC
C10: Input | E10: Input Measurement | J10: Output 1 Measurement | R10: Input | T10: Input Measurement | Y10: Output 1 Measurement | AG10: Input | AI10: Input Measurement | AN10: Output 1 Measurement | AW10: Input | AY10: Input Measurement | BD10: Output 1 Measurement | BL10: Input | BN10: Input Measurement | BS10: Output 1 Measurement | CA10: Input | CC10: Input Measurement | CH10: Output 1 Measurement | CQ10: Input | CS10: Input Measurement | CX10: Output 1 Measurement | DF10: Input | DH10: Input Measurement | DM10: Output 1 Measurement | DU10: Input | DW10: Input Measurement | EB10: Output 1 Measurement
C11: Vac (rms) | D11: Freq (Hz) | E11: Vin (rms) | F11: Iin (mA) | G11: Pin (W) | H11: PF | I11: % THD | J11: Vo (V) | K11: Io (mA) | L11: Po (W) | M11: %I Reg | N11: Efficiency | R11: Vac (rms) | S11: Freq (Hz) | T11: Vin (rms) | U11: Iin (mA) | V11: Pin (W) | W11: PF | X11: % THD | Y11: Vo (V) | Z11: Io (mA) | AA11: Po (W) | AB11: %I Reg | AC11: Efficiency | AG11: Vac (rms) | AH11: Freq (Hz) | AI11: Vin (rms) | AJ11: Iin (mA) | AK11: Pin (W) | AL11: PF | AM11: % THD | AN11: Vo (V) | AO11: Io (mA) | AP11: Po (W) | AQ11: %I Reg | AR11: Efficiency | AW11: Vac (rms) | AX11: Freq (Hz) | AY11: Vin (rms) | AZ11: Iin (mA) | BA11: Pin (W) | BB11: PF | BC11: % THD | BD11: Vo (V) | BE11: Io (mA) | BF11: Po (W) | BG11: %I Reg | BH11: Efficiency | BL11: Vac (rms) | BM11: Freq (Hz) | BN11: Vin (rms) | BO11: Iin (mA) | BP11: Pin (W) | BQ11: PF | BR11: % THD | BS11: Vo (V) | BT11: Io (mA) | BU11: Po (W) | BV11: %I Reg | BW11: Efficiency | CA11: Vac (rms) | CB11: Freq (Hz) | CC11: Vin (rms) | CD11: Iin (mA) | CE11: Pin (W) | CF11: PF | CG11: % THD | CH11: Vo (V) | CI11: Io (mA) | CJ11: Po (W) | CK11: %I Reg | CL11: Efficiency | CQ11: Vac (rms) | CR11: Freq (Hz) | CS11: Vin (rms) | CT11: Iin (mA) | CU11: Pin (W) | CV11: PF | CW11: % THD | CX11: Vo (V) | CY11: Io (mA) | CZ11: Po (W) | DA11: %I Reg | DB11: Efficiency | DF11: Vac (rms) | DG11: Freq (Hz) | DH11: Vin (rms) | DI11: Iin (mA) | DJ11: Pin (W) | DK11: PF | DL11: % THD | DM11: Vo (V) | DN11: Io (mA) | DO11: Po (W) | DP11: %I Reg | DQ11: Efficiency | DU11: Vac (rms) | DV11: Freq (Hz) | DW11: Vin (rms) | DX11: Iin (mA) | DY11: Pin (W) | DZ11: PF | EA11: % THD | EB11: Vo (V) | EC11: Io (mA) | ED11: Po (W) | EE11: %I Reg | EF11: Efficiency
B12: 10 | C12: 120 | D12: 60 | E12: 119.9 | F12: 341.15 | G12: 40.545 | H12: 0.9912 | I12: 4.321 | J12: 47.703 | K12: 755.1 | L12: 35.984 | M12: -3.1923077 | N12: 88.750771 | Q12: 10 | R12: 230 | S12: 50 | T12: 229.86 | U12: 183.77 | V12: 40.251 | W12: 0.9529 | X12: 6.918 | Y12: 47.684 | Z12: 754.8 | AA12: 35.957 | AB12: -3.2307692 | AC12: 89.331942 | AF12: 10 | AG12: 277 | AH12: 60 | AI12: 276.89 | AJ12: 161.22 | AK12: 40.22 | AL12: 0.9011 | AM12: 9.171 | AN12: 47.599 | AO12: 754.4 | AP12: 35.874 | AQ12: -3.2820513 | AR12: 89.194431 | AV12: 10 | AW12: 120 | AX12: 60 | AY12: 119.92 | AZ12: 259.55 | BA12: 30.72 | BB12: 0.987 | BC12: 4.432 | BD12: 36.026 | BE12: 754.3 | BF12: 27.148 | BG12: -3.2948718 | BH12: 88.372396 | BK12: 10 | BL12: 230 | BM12: 50 | BN12: 229.89 | BO12: 143.67 | BP12: 30.629 | BQ12: 0.9274 | BR12: 8.156 | BS12: 36.006 | BT12: 754 | BU12: 27.121 | BV12: -3.3333333 | BW12: 88.546802 | BZ12: 10 | CA12: 277 | CB12: 60 | CC12: 276.92 | CD12: 130.04 | CE12: 30.711 | CF12: 0.8529 | CG12: 12.209 | CH12: 35.98 | CI12: 754 | CJ12: 27.1 | CK12: -3.3333333 | CL12: 88.241998 | CP12: 10 | CQ12: 120 | CR12: 60 | CS12: 119.84 | CT12: 175.75 | CU12: 20.496 | CV12: 0.9731 | CW12: 6.045 | CX12: 23.705 | CY12: 752.8 | CZ12: 17.827 | DA12: -3.4871795 | DB12: 86.977947 | DE12: 10 | DF12: 230 | DG12: 50 | DH12: 229.83 | DI12: 104.65 | DJ12: 20.792 | DK12: 0.8644 | DL12: 13.228 | DM12: 23.867 | DN12: 753.8 | DO12: 17.969 | DP12: -3.3589744 | DQ12: 86.422663 | DT12: 10 | DU12: 277 | DV12: 60 | DW12: 276.85 | DX12: 99.49 | DY12: 20.897 | DZ12: 0.7587 | EA12: 17.77 | EB12: 23.842 | EC12: 754.5 | ED12: 17.966 | EE12: -3.2692308 | EF12: 85.974063
B13: 9 | C13: 120 | D13: 60 | E13: 119.9 | F13: 340.95 | G13: 40.52 | H13: 0.9912 | I13: 4.286 | J13: 47.688 | K13: 755 | L13: 35.969 | M13: -3.2051282 | N13: 88.768509 | Q13: 9 | R13: 230 | S13: 50 | T13: 229.86 | U13: 183.64 | V13: 40.219 | W13: 0.9528 | X13: 6.917 | Y13: 47.669 | Z13: 754.6 | AA13: 35.939 | AB13: -3.2564103 | AC13: 89.358264 | AF13: 9 | AG13: 277 | AH13: 60 | AI13: 276.89 | AJ13: 161.14 | AK13: 40.198 | AL13: 0.901 | AM13: 9.84 | AN13: 47.587 | AO13: 754.3 | AP13: 35.858 | AQ13: -3.2948718 | AR13: 89.203443 | AV13: 9 | AW13: 120 | AX13: 60 | AY13: 119.92 | AZ13: 259.37 | BA13: 30.693 | BB13: 0.9869 | BC13: 4.079 | BD13: 36.018 | BE13: 754.1 | BF13: 27.134 | BG13: -3.3205128 | BH13: 88.404522 | BK13: 9 | BL13: 230 | BM13: 50 | BN13: 229.89 | BO13: 143.61 | BP13: 30.618 | BQ13: 0.9273 | BR13: 8.174 | BS13: 35.999 | BT13: 753.9 | BU13: 27.112 | BV13: -3.3461538 | BW13: 88.549219 | BZ13: 9 | CA13: 277 | CB13: 60 | CC13: 276.92 | CD13: 129.99 | CE13: 30.697 | CF13: 0.8528 | CG13: 11.889 | CH13: 35.973 | CI13: 753.9 | CJ13: 27.093 | CK13: -3.3461538 | CL13: 88.259439 | CP13: 9 | CQ13: 120 | CR13: 60 | CS13: 119.84 | CT13: 175.7 | CU13: 20.49 | CV13: 0.9731 | CW13: 5.583 | CX13: 23.702 | CY13: 752.9 | CZ13: 17.825 | DA13: -3.474359 | DB13: 86.993655 | DE13: 9 | DF13: 230 | DG13: 50 | DH13: 229.84 | DI13: 104.6 | DJ13: 20.779 | DK13: 0.8644 | DL13: 13.339 | DM13: 23.861 | DN13: 753.7 | DO13: 17.962 | DP13: -3.3717949 | DQ13: 86.443043 | DT13: 9 | DU13: 277 | DV13: 60 | DW13: 276.85 | DX13: 99.45 | DY13: 20.886 | DZ13: 0.7586 | EA13: 18.622 | EB13: 23.838 | EC13: 754.4 | ED13: 17.962 | EE13: -3.2820513 | EF13: 86.000192
B14: 8 | C14: 120 | D14: 60 | E14: 119.91 | F14: 296.17 | G14: 35.169 | H14: 0.9904 | I14: 4.126 | J14: 47.185 | K14: 663.1 | L14: 31.255 | M14: -14.987179 | N14: 88.870881 | Q14: 8 | R14: 230 | S14: 50 | T14: 229.88 | U14: 161.73 | V14: 35.047 | W14: 0.9426 | X14: 7.484 | Y14: 47.175 | Z14: 663.7 | AA14: 31.28 | AB14: -14.910256 | AC14: 89.251576 | AF14: 8 | AG14: 277 | AH14: 60 | AI14: 276.91 | AJ14: 143.72 | AK14: 35.031 | AL14: 0.8803 | AM14: 10.5 | AN14: 47.094 | AO14: 663.1 | AP14: 31.2 | AQ14: -14.987179 | AR14: 89.063972 | AV14: 8 | AW14: 120 | AX14: 60 | AY14: 119.92 | AZ14: 226.5 | BA14: 26.723 | BB14: 0.9837 | BC14: 4.055 | BD14: 35.632 | BE14: 663.6 | BF14: 23.622 | BG14: -14.923077 | BH14: 88.395764 | BK14: 8 | BL14: 230 | BM14: 50 | BN14: 229.9 | BO14: 127.35 | BP14: 26.699 | BQ14: 0.9119 | BR14: 8.601 | BS14: 35.615 | BT14: 663.5 | BU14: 23.607 | BV14: -14.935897 | BW14: 88.419042 | BZ14: 8 | CA14: 277 | CB14: 60 | CC14: 276.93 | CD14: 117.18 | CE14: 26.78 | CF14: 0.8253 | CG14: 13.293 | CH14: 35.59 | CI14: 663.3 | CJ14: 23.58 | CK14: -14.961538 | CL14: 88.050784 | CP14: 8 | CQ14: 120 | CR14: 60 | CS14: 119.86 | CT14: 154 | CU14: 17.856 | CV14: 0.9673 | CW14: 5.667 | CX14: 23.485 | CY14: 662.4 | CZ14: 15.54 | DA14: -15.076923 | DB14: 87.02957 | DE14: 8 | DF14: 230 | DG14: 50 | DH14: 229.84 | DI14: 93.98 | DJ14: 18.157 | DK14: 0.8405 | DL14: 14.169 | DM14: 23.64 | DN14: 664 | DO14: 15.678 | DP14: -14.871795 | DQ14: 86.346863 | DT14: 8 | DU14: 277 | DV14: 60 | DW14: 276.86 | DX14: 91.15 | DY14: 18.256 | DZ14: 0.7234 | EA14: 20.192 | EB14: 23.618 | EC14: 664.1 | ED14: 15.666 | EE14: -14.858974 | EF14: 85.812883
B15: 7 | C15: 120 | D15: 60 | E15: 119.91 | F15: 245.69 | G15: 29.071 | H15: 0.9867 | I15: 4.084 | J15: 46.566 | K15: 555.2 | L15: 25.827 | M15: -28.820513 | N15: 88.841113 | Q15: 7 | R15: 230 | S15: 50 | T15: 229.89 | U15: 136.46 | V15: 29.023 | W15: 0.925 | X15: 7.662 | Y15: 46.558 | Z15: 555.5 | AA15: 25.835 | AB15: -28.782051 | AC15: 89.015608 | AF15: 7 | AG15: 277 | AH15: 60 | AI15: 276.92 | AJ15: 124.01 | AK15: 29.067 | AL15: 0.8464 | AM15: 11.909 | AN15: 46.486 | AO15: 555.5 | AP15: 25.794 | AQ15: -28.782051 | AR15: 88.739808 | AV15: 7 | AW15: 120 | AX15: 60 | AY15: 119.93 | AZ15: 188.77 | BA15: 22.134 | BB15: 0.9778 | BC15: 3.919 | BD15: 35.155 | BE15: 557 | BF15: 19.563 | BG15: -28.589744 | BH15: 88.384386 | BK15: 7 | BL15: 230 | BM15: 50 | BN15: 229.92 | BO15: 108.8 | BP15: 22.157 | BQ15: 0.8858 | BR15: 9.578 | BS15: 35.138 | BT15: 556.6 | BU15: 19.537 | BV15: -28.641026 | BW15: 88.175294 | BZ15: 7 | CA15: 277 | CB15: 60 | CC15: 276.94 | CD15: 102.8 | CE15: 22.247 | CF15: 0.7815 | CG15: 16.167 | CH15: 35.116 | CI15: 556.6 | CJ15: 19.525 | CK15: -28.641026 | CL15: 87.764642 | CP15: 7 | CQ15: 120 | CR15: 60 | CS15: 119.87 | CT15: 129.33 | CU15: 14.825 | CV15: 0.9562 | CW15: 6.494 | CX15: 23.218 | CY15: 556.1 | CZ15: 12.898 | DA15: -28.705128 | DB15: 87.001686 | DE15: 7 | DF15: 230 | DG15: 50 | DH15: 229.85 | DI15: 82.03 | DJ15: 15.114 | DK15: 0.8016 | DL15: 15.709 | DM15: 23.369 | DN15: 557.8 | DO15: 13.018 | DP15: -28.487179 | DQ15: 86.132063 | DT15: 7 | DU15: 277 | DV15: 60 | DW15: 276.86 | DX15: 81.63 | DY15: 15.205 | DZ15: 0.6727 | EA15: 22.088 | EB15: 23.346 | EC15: 557.6 | ED15: 13.003 | EE15: -28.512821 | EF15: 85.517922
B16: 6 | C16: 120 | D16: 60 | E16: 119.92 | F16: 197.51 | G16: 23.223 | H16: 0.9805 | I16: 4.35 | J16: 45.921 | K16: 449.4 | L16: 20.615 | M16: -42.384615 | N16: 88.769754 | Q16: 6 | R16: 230 | S16: 50 | T16: 229.91 | U16: 112.66 | V16: 23.227 | W16: 0.8967 | X16: 8.761 | Y16: 45.911 | Z16: 449 | AA16: 20.59 | AB16: -42.435897 | AC16: 88.646833 | AF16: 6 | AG16: 277 | AH16: 60 | AI16: 276.93 | AJ16: 105.54 | AK16: 23.294 | AL16: 0.797 | AM16: 14.429 | AN16: 45.845 | AO16: 449.1 | AP16: 20.569 | AQ16: -42.423077 | AR16: 88.301709 | AV16: 6 | AW16: 120 | AX16: 60 | AY16: 119.93 | AZ16: 151.91 | BA16: 17.636 | BB16: 0.9678 | BC16: 4.402 | BD16: 34.645 | BE16: 449.6 | BF16: 15.562 | BG16: -42.358974 | BH16: 88.239964 | BK16: 6 | BL16: 230 | BM16: 50 | BN16: 229.93 | BO16: 91.16 | BP16: 17.714 | BQ16: 0.8452 | BR16: 12.072 | BS16: 34.63 | BT16: 449.6 | BU16: 15.553 | BV16: -42.358974 | BW16: 87.80061 | BZ16: 6 | CA16: 277 | CB16: 60 | CC16: 276.95 | CD16: 89.04 | CE16: 17.805 | CF16: 0.7219 | CG16: 18.35 | CH16: 34.607 | CI16: 449.5 | CJ16: 15.539 | CK16: -42.371795 | CL16: 87.273238 | CP16: 6 | CQ16: 120 | CR16: 60 | CS16: 119.89 | CT16: 105.54 | CU16: 11.857 | CV16: 0.9371 | CW16: 7.831 | CX16: 22.938 | CY16: 449.8 | CZ16: 10.305 | DA16: -42.333333 | DB16: 86.910686 | DE16: 6 | DF16: 230 | DG16: 50 | DH16: 229.86 | DI16: 70.7 | DJ16: 12.134 | DK16: 0.7466 | DL16: 18.355 | DM16: 23.081 | DN16: 451.4 | DO16: 10.407 | DP16: -42.128205 | DQ16: 85.767266 | DT16: 6 | DU16: 277 | DV16: 60 | DW16: 276.87 | DX16: 72.52 | DY16: 12.226 | DZ16: 0.6089 | EA16: 24.898 | EB16: 23.059 | EC16: 451.1 | ED16: 10.39 | EE16: -42.166667 | EF16: 84.982823
B17: 5 | C17: 120 | D17: 60 | E17: 119.93 | F17: 151.18 | G17: 17.579 | H17: 0.9697 | I17: 5.257 | J17: 45.22 | K17: 343.1 | L17: 15.498 | M17: -56.012821 | N17: 88.162011 | Q17: 5 | R17: 230 | S17: 50 | T17: 229.93 | U17: 90.19 | V17: 17.564 | W17: 0.847 | X17: 10.982 | Y17: 45.208 | Z17: 342 | AA17: 15.446 | AB17: -56.153846 | AC17: 87.941243 | AF17: 5 | AG17: 277 | AH17: 60 | AI17: 276.95 | AJ17: 88.41 | AK17: 17.71 | AL17: 0.7233 | AM17: 18.903 | AN17: 45.153 | AO17: 343.2 | AP17: 15.483 | AQ17: -56 | AR17: 87.425184 | AV17: 5 | AW17: 120 | AX17: 60 | AY17: 119.88 | AZ17: 116.38 | BA17: 13.261 | BB17: 0.9505 | BC17: 6.296 | BD17: 34.092 | BE17: 342.5 | BF17: 11.662 | BG17: -56.089744 | BH17: 87.942086 | BK17: 5 | BL17: 230 | BM17: 50 | BN17: 229.94 | BO17: 74.63 | BP17: 13.386 | BQ17: 0.78 | BR17: 14.401 | BS17: 34.078 | BT17: 342.5 | BU17: 11.658 | BV17: -56.089744 | BW17: 87.090991 | BZ17: 5 | CA17: 277 | CB17: 60 | CC17: 276.96 | CD17: 76.29 | CE17: 13.519 | CF17: 0.6398 | CG17: 22.234 | CH17: 34.063 | CI17: 343.2 | CJ17: 11.679 | CK17: -56 | CL17: 86.389526 | CP17: 5 | CQ17: 120 | CR17: 60 | CS17: 119.9 | CT17: 82.95 | CU17: 8.963 | CV17: 0.9011 | CW17: 7.554 | CX17: 22.631 | CY17: 342.9 | CZ17: 7.751 | DA17: -56.038462 | DB17: 86.477742 | DE17: 5 | DF17: 230 | DG17: 50 | DH17: 229.87 | DI17: 59.98 | DJ17: 9.199 | DK17: 0.6673 | DL17: 22.57 | DM17: 22.765 | DN17: 344 | DO17: 7.822 | DP17: -55.897436 | DQ17: 85.030982 | DT17: 5 | DU17: 277 | DV17: 60 | DW17: 276.88 | DX17: 63.65 | DY17: 9.294 | DZ17: 0.5274 | EA17: 29.435 | EB17: 22.747 | EC17: 344 | ED17: 7.816 | EE17: -55.897436 | EF17: 84.097267
B18: 4 | C18: 120 | D18: 60 | E18: 119.88 | F18: 106.14 | G18: 11.991 | H18: 0.9421 | I18: 5.085 | J18: 44.432 | K18: 236.13 | L18: 10.478 | M18: -69.726923 | N18: 87.382203 | Q18: 4 | R18: 230 | S18: 50 | T18: 229.94 | U18: 69.58 | V18: 12.075 | W18: 0.7547 | X18: 15.413 | Y18: 44.427 | Z18: 235.9 | AA18: 10.468 | AB18: -69.75641 | AC18: 86.691511 | AF18: 4 | AG18: 277 | AH18: 60 | AI18: 276.96 | AJ18: 72.25 | AK18: 12.218 | AL18: 0.6106 | AM18: 23.671 | AN18: 44.377 | AO18: 236.84 | AP18: 10.501 | AQ18: -69.635897 | AR18: 85.946963 | AV18: 4 | AW18: 120 | AX18: 60 | AY18: 119.9 | AZ18: 83.25 | BA18: 9.048 | BB18: 0.9065 | BC18: 8.187 | BD18: 33.475 | BE18: 235.65 | BF18: 7.879 | BG18: -69.788462 | BH18: 87.080018 | BK18: 4 | BL18: 230 | BM18: 50 | BN18: 229.95 | BO18: 59.65 | BP18: 9.2 | BQ18: 0.6709 | BR18: 19.617 | BS18: 33.465 | BT18: 236 | BU18: 7.888 | BV18: -69.74359 | BW18: 85.73913 | BZ18: 4 | CA18: 277 | CB18: 60 | CC18: 276.97 | CD18: 64.09 | CE18: 9.329 | CF18: 0.5255 | CG18: 28.014 | CH18: 33.454 | CI18: 236.78 | CJ18: 7.914 | CK18: -69.64359 | CL18: 84.832244 | CP18: 4 | CQ18: 120 | CR18: 60 | CS18: 119.92 | CT18: 61.89 | CU18: 6.126 | CV18: 0.8254 | CW18: 13.363 | CX18: 22.286 | CY18: 236.05 | CZ18: 5.254 | DA18: -69.737179 | DB18: 85.765589 | DE18: 4 | DF18: 230 | DG18: 50 | DH18: 229.88 | DI18: 49.94 | DJ18: 6.344 | DK18: 0.5526 | DL18: 28.13 | DM18: 22.411 | DN18: 237.16 | DO18: 5.308 | DP18: -69.594872 | DQ18: 83.669609 | DT18: 4 | DU18: 277 | DV18: 60 | DW18: 276.89 | DX18: 55.88 | DY18: 6.457 | DZ18: 0.4173 | EA18: 33.87 | EB18: 22.395 | EC18: 237.37 | ED18: 5.31 | EE18: -69.567949 | EF18: 82.236333
B19: 3 | C19: 120 | D19: 60 | E19: 119.92 | F19: 115.41 | G19: 6.091 | H19: 0.4394 | I19: 87.708 | J19: 43.39 | K19: 113.94 | L19: 4.943 | M19: -85.392308 | N19: 81.15252 | Q19: 3 | R19: 230 | S19: 50 | T19: 229.95 | U19: 77.16 | V19: 6.142 | W19: 0.3462 | X19: 52.873 | Y19: 43.389 | Z19: 113.9 | AA19: 4.941 | AB19: -85.397436 | AC19: 80.446109 | AF19: 3 | AG19: 277 | AH19: 60 | AI19: 276.97 | AJ19: 67.38 | AK19: 6.211 | AL19: 0.3327 | AM19: 42.305 | AN19: 43.335 | AO19: 113.87 | AP19: 4.934 | AQ19: -85.401282 | AR19: 79.439704 | AV19: 3 | AW19: 120 | AX19: 60 | AY19: 119.92 | AZ19: 97.35 | BA19: 4.892 | BB19: 0.4185 | BC19: 82.517 | BD19: 32.74 | BE19: 121.5 | BF19: 3.9771 | BG19: -84.423077 | BH19: 81.298038 | BK19: 3 | BL19: 230 | BM19: 50 | BN19: 229.96 | BO19: 65.35 | BP19: 4.949 | BQ19: 0.3295 | BR19: 45.94 | BS19: 32.728 | BT19: 121.33 | BU19: 3.97 | BV19: -84.444872 | BW19: 80.218226 | BZ19: 3 | CA19: 277 | CB19: 60 | CC19: 276.98 | CD19: 57.41 | CE19: 5.048 | CF19: 0.3177 | CG19: 41.071 | CH19: 32.713 | CI19: 121.48 | CJ19: 3.9738 | CK19: -84.425641 | CL19: 78.720285 | CP19: 3 | CQ19: 120 | CR19: 60 | CS19: 119.93 | CT19: 73.61 | CU19: 3.435 | CV19: 0.3892 | CW19: 71.598 | CX19: 21.918 | CY19: 127.29 | CZ19: 2.7896 | DA19: -83.680769 | DB19: 81.211063 | DE19: 3 | DF19: 230 | DG19: 50 | DH19: 229.89 | DI19: 47.82 | DJ19: 3.558 | DK19: 0.3236 | DL19: 42.799 | DM19: 22.034 | DN19: 127.28 | DO19: 2.804 | DP19: -83.682051 | DQ19: 78.808319 | DT19: 3 | DU19: 277 | DV19: 60 | DW19: 276.89 | DX19: 47.78 | DY19: 3.682 | DZ19: 0.2783 | EA19: 37.538 | EB19: 22.019 | EC19: 127.42 | ED19: 2.8052 | EE19: -83.664103 | EF19: 76.186855
B20: 2 | C20: 120 | D20: 60 | E20: 119.94 | F20: 35.16 | G20: 1.181 | H20: 0.2801 | I20: 47.106 | J20: 41.836 | K20: 20.25 | L20: 0.8471 | M20: -97.403846 | N20: 71.72735 | Q20: 2 | R20: 230 | S20: 50 | T20: 229.97 | U20: 31.05 | V20: 1.279 | W20: 0.179 | X20: 34.109 | Y20: 41.838 | Z20: 20.297 | AA20: 0.8491 | AB20: -97.397821 | AC20: 66.387803 | AF20: 2 | AG20: 277 | AH20: 60 | AI20: 276.98 | AJ20: 36.51 | AK20: 1.308 | AL20: 0.1294 | AM20: 23.514 | AN20: 41.791 | AO20: 20.497 | AP20: 0.8565 | AQ20: -97.372179 | AR20: 65.481651 | AV20: 2 | AW20: 120 | AX20: 60 | AY20: 119.95 | AZ20: 31.8 | BA20: 0.963 | BB20: 0.2525 | BC20: 49.03 | BD20: 31.469 | BE20: 20.925 | BF20: 0.6585 | BG20: -97.317308 | BH20: 68.380062 | BK20: 2 | BL20: 230 | BM20: 50 | BN20: 229.97 | BO20: 30.16 | BP20: 1.078 | BQ20: 0.1554 | BR20: 27.948 | BS20: 31.485 | BT20: 21.99 | BU20: 0.6923 | BV20: -97.180769 | BW20: 64.220779 | BZ20: 2 | CA20: 277 | CB20: 60 | CC20: 276.99 | CD20: 35.68 | CE20: 1.052 | CF20: 0.1064 | CG20: 21.404 | CH20: 31.437 | CI20: 20.735 | CJ20: 0.6518 | CK20: -97.341667 | CL20: 61.958175 | CP20: 2 | CQ20: 120 | CR20: 60 | CS20: 119.95 | CT20: 31.29 | CU20: 0.931 | CV20: 0.2481 | CW20: 47.317 | CX20: 21.221 | CY20: 31.29 | CZ20: 0.664 | DA20: -95.988462 | DB20: 71.32116 | DE20: 2 | DF20: 230 | DG20: 50 | DH20: 229.89 | DI20: 29.598 | DJ20: 0.973 | DK20: 0.1429 | DL20: 31.306 | DM20: 21.324 | DN20: 30.13 | DO20: 0.6423 | DP20: -96.137179 | DQ20: 66.012333 | DT20: 2 | DU20: 277 | DV20: 60 | DW20: 276.9 | DX20: 35.43 | DY20: 1.002 | DZ20: 0.1021 | EA20: 19.852 | EB20: 21.309 | EC20: 30.27 | ED20: 0.6449 | EE20: -96.119231 | EF20: 64.361277
B21: 1 | C21: 120 | D21: 60 | E21: 119.95 | F21: 27.192 | G21: 0.537 | H21: 0.1646 | I21: 47.096 | J21: 41.197 | K21: 7.192 | L21: 0.2963 | M21: -99.077949 | N21: 55.176909 | Q21: 1 | R21: 230 | S21: 50 | T21: 229.97 | U21: 28.21 | V21: 0.534 | W21: 0.0824 | X21: 18.529 | Y21: 41.168 | Z21: 6.843 | AA21: 0.2817 | AB21: -99.122692 | AC21: 52.752809 | AF21: 1 | AG21: 277 | AH21: 60 | AI21: 276.98 | AJ21: 34.38 | AK21: 0.565 | AL21: 0.0593 | AM21: 13.593 | AN21: 41.117 | AO21: 6.883 | AP21: 0.283 | AQ21: -99.117564 | AR21: 50.088496 | AV21: 1 | AW21: 120 | AX21: 60 | AY21: 119.95 | AZ21: 26.423 | BA21: 0.4297 | BB21: 0.1356 | BC21: 32.196 | BD21: 30.981 | BE21: 7.574 | BF21: 0.23463 | BG21: -99.028974 | BH21: 54.603212 | BK21: 1 | BL21: 230 | BM21: 50 | BN21: 229.97 | BO21: 27.946 | BP21: 0.441 | BQ21: 0.0686 | BR21: 24.083 | BS21: 30.957 | BT21: 7.376 | BU21: 0.22832 | BV21: -99.054359 | BW21: 51.773243 | BZ21: 1 | CA21: 277 | CB21: 60 | CC21: 276.99 | CD21: 34.22 | CE21: 0.479 | CF21: 0.0505 | CG21: 21.13 | CH21: 30.954 | CI21: 7.613 | CJ21: 0.23565 | CK21: -99.023974 | CL21: 49.196242 | CP21: 1 | CQ21: 120 | CR21: 60 | CS21: 119.95 | CT21: 31.25 | CU21: 0.93 | CV21: 0.2482 | CW21: 48.347 | CX21: 21.226 | CY21: 31.22 | CZ21: 0.6627 | DA21: -95.997436 | DB21: 71.258065 | DE21: 1 | DF21: 230 | DG21: 50 | DH21: 229.9 | DI21: 29.596 | DJ21: 0.972 | DK21: 0.1428 | DL21: 30.555 | DM21: 21.327 | DN21: 30.09 | DO21: 0.6417 | DP21: -96.142308 | DQ21: 66.018519 | DT21: 1 | DU21: 277 | DV21: 60 | DW21: 276.9 | DX21: 35.42 | DY21: 1.001 | DZ21: 0.1021 | EA21: 26.913 | EB21: 21.314 | EC21: 30.23 | ED21: 0.6442 | EE21: -96.124359 | EF21: 64.355644
B22: 0 | C22: 120 | D22: 60 | E22: 119.95 | F22: 24.822 | G22: 0.0684 | H22: 0.023 | I22: 37.186 | J22: 35.477 | K22: 0 | L22: 0.00021 | M22: -100 | N22: 0.30701754 | Q22: 0 | R22: 230 | S22: 50 | T22: 229.97 | U22: 27.353 | V22: 0.178 | W22: 0.0283 | X22: 7.528 | Y22: 35.479 | Z22: 0 | AA22: 0.00023 | AB22: -100 | AC22: 0.12921348 | AF22: 0 | AG22: 277 | AH22: 60 | AI22: 276.99 | AJ22: 33.78 | AK22: 0.24 | AL22: 0.0256 | AM22: 18.939 | AN22: 35.389 | AO22: 0 | AP22: 0.00021 | AQ22: -100 | AR22: 0.0875 | AV22: 0 | AW22: 120 | AX22: 60 | AY22: 119.95 | AZ22: 24.85 | BA22: 0.0708 | BB22: 0.0238 | BC22: 17.448 | BD22: 26.399 | BE22: 0 | BF22: 0.00013 | BG22: -100 | BH22: 0.18361582 | BK22: 0 | BL22: 230 | BM22: 50 | BN22: 229.98 | BO22: 27.35 | BP22: 0.177 | BQ22: 0.0281 | BR22: 8.424 | BS22: 26.38 | BT22: 0 | BU22: 0.00012 | BV22: -100 | BW22: 0.06779661 | BZ22: 0 | CA22: 277 | CB22: 60 | CC22: 276.99 | CD22: 33.78 | CE22: 0.242 | CF22: 0.0258 | CG22: 6.497 | CH22: 26.35 | CI22: 0 | CJ22: 0.00011 | CK22: -100 | CL22: 0.045454545 | CP22: 0 | CQ22: 120 | CR22: 60 | CS22: 119.95 | CT22: 24.857 | CU22: 0.07 | CV22: 0.0235 | CW22: 11.207 | CX22: 17.476 | CY22: 0 | CZ22: 6e-05 | DA22: -100 | DB22: 0.085714286 | DE22: 0 | DF22: 230 | DG22: 50 | DH22: 229.9 | DI22: 27.157 | DJ22: 0.177 | DK22: 0.0283 | DL22: 19.897 | DM22: 17.644 | DN22: 0 | DO22: 0.00013 | DP22: -100 | DQ22: 0.073446328 | DT22: 0 | DU22: 277 | DV22: 60 | DW22: 276.9 | DX22: 33.66 | DY22: 0.239 | DZ22: 0.0256 | EA22: 17.636 | EB22: 17.644 | EC22: 0 | ED22: 0.0001 | EE22: -100 | EF22: 0.041841004

Sheet Resistor Dimming
A2: Legacy Dimming: Resistor
A3: ='PF, THD, EFF'!A3:H3
B8: 48V LED, 120 VAC | Q8: 48V LED, 230 VAC | AF8: 48V LED, 277 VAC | AV8: 36V LED, 120 VAC | BK8: 36V LED, 230 VAC | BZ8: 36V LED, 277 VAC | CP8: 24V LED, 120 VAC | DE8: 24V LED, 230 VAC | DT8: 24V LED, 277 VAC
C10: Input | E10: Input Measurement | J10: Output 1 Measurement | R10: Input | T10: Input Measurement | Y10: Output 1 Measurement | AG10: Input | AI10: Input Measurement | AN10: Output 1 Measurement | AW10: Input | AY10: Input Measurement | BD10: Output 1 Measurement | BL10: Input | BN10: Input Measurement | BS10: Output 1 Measurement | CA10: Input | CC10: Input Measurement | CH10: Output 1 Measurement | CQ10: Input | CS10: Input Measurement | CX10: Output 1 Measurement | DF10: Input | DH10: Input Measurement | DM10: Output 1 Measurement | DU10: Input | DW10: Input Measurement | EB10: Output 1 Measurement
C11: Vac (rms) | D11: Freq (Hz) | E11: Vin (rms) | F11: Iin (mA) | G11: Pin (W) | H11: PF | I11: % THD | J11: Vo (V) | K11: Io (mA) | L11: Po (W) | M11: %I Reg | N11: Efficiency | R11: Vac (rms) | S11: Freq (Hz) | T11: Vin (rms) | U11: Iin (mA) | V11: Pin (W) | W11: PF | X11: % THD | Y11: Vo (V) | Z11: Io (mA) | AA11: Po (W) | AB11: %I Reg | AC11: Efficiency | AG11: Vac (rms) | AH11: Freq (Hz) | AI11: Vin (rms) | AJ11: Iin (mA) | AK11: Pin (W) | AL11: PF | AM11: % THD | AN11: Vo (V) | AO11: Io (mA) | AP11: Po (W) | AQ11: %I Reg | AR11: Efficiency | AW11: Vac (rms) | AX11: Freq (Hz) | AY11: Vin (rms) | AZ11: Iin (mA) | BA11: Pin (W) | BB11: PF | BC11: % THD | BD11: Vo (V) | BE11: Io (mA) | BF11: Po (W) | BG11: %I Reg | BH11: Efficiency | BL11: Vac (rms) | BM11: Freq (Hz) | BN11: Vin (rms) | BO11: Iin (mA) | BP11: Pin (W) | BQ11: PF | BR11: % THD | BS11: Vo (V) | BT11: Io (mA) | BU11: Po (W) | BV11: %I Reg | BW11: Efficiency | CA11: Vac (rms) | CB11: Freq (Hz) | CC11: Vin (rms) | CD11: Iin (mA) | CE11: Pin (W) | CF11: PF | CG11: % THD | CH11: Vo (V) | CI11: Io (mA) | CJ11: Po (W) | CK11: %I Reg | CL11: Efficiency | CQ11: Vac (rms) | CR11: Freq (Hz) | CS11: Vin (rms) | CT11: Iin (mA) | CU11: Pin (W) | CV11: PF | CW11: % THD | CX11: Vo (V) | CY11: Io (mA) | CZ11: Po (W) | DA11: %I Reg | DB11: Efficiency | DF11: Vac (rms) | DG11: Freq (Hz) | DH11: Vin (rms) | DI11: Iin (mA) | DJ11: Pin (W) | DK11: PF | DL11: % THD | DM11: Vo (V) | DN11: Io (mA) | DO11: Po (W) | DP11: %I Reg | DQ11: Efficiency | DU11: Vac (rms) | DV11: Freq (Hz) | DW11: Vin (rms) | DX11: Iin (mA) | DY11: Pin (W) | DZ11: PF | EA11: % THD | EB11: Vo (V) | EC11: Io (mA) | ED11: Po (W) | EE11: %I Reg | EF11: Efficiency
B12: 100 | C12: 120 | D12: 60 | E12: 119.88 | F12: 341.8 | G12: 40.618 | H12: 0.9913 | I12: 4.257 | J12: 47.777 | K12: 755.1 | L12: 36.045 | M12: -3.1923077 | N12: 88.741445 | Q12: 100 | R12: 230 | S12: 50 | T12: 229.81 | U12: 183.77 | V12: 40.247 | W12: 0.953 | X12: 6.974 | Y12: 47.686 | Z12: 754.7 | AA12: 35.951 | AB12: -3.2435897 | AC12: 89.325912 | AF12: 100 | AG12: 277 | AH12: 50 | AI12: 276.81 | AJ12: 158.24 | AK12: 40.252 | AL12: 0.919 | AM12: 8.997 | AN12: 47.621 | AO12: 754.4 | AP12: 35.889 | AQ12: -3.2820513 | AR12: 89.160787 | AV12: 100 | AW12: 120 | AX12: 60 | AY12: 119.89 | AZ12: 259.38 | BA12: 30.694 | BB12: 0.987 | BC12: 4.032 | BD12: 36.007 | BE12: 754.2 | BF12: 27.128 | BG12: -3.3076923 | BH12: 88.382094 | BK12: 100 | BL12: 230 | BM12: 50 | BN12: 229.84 | BO12: 143.7 | BP12: 30.633 | BQ12: 0.9274 | BR12: 8.495 | BS12: 36.002 | BT12: 754.1 | BU12: 27.122 | BV12: -3.3205128 | BW12: 88.538504 | BZ12: 100 | CA12: 277 | CB12: 60 | CC12: 276.86 | CD12: 130.2 | CE12: 30.755 | CF12: 0.8532 | CG12: 11.865 | CH12: 35.993 | CI12: 754.5 | CJ12: 27.128 | CK12: -3.2692308 | CL12: 88.206796 | CP12: 100 | CQ12: 120 | CR12: 60 | CS12: 119.81 | CT12: 175.98 | CU12: 20.521 | CV12: 0.9732 | CW12: 5.88 | CX12: 23.722 | CY12: 753.1 | CZ12: 17.845 | DA12: -3.4487179 | DB12: 86.9597 | DE12: 100 | DF12: 230 | DG12: 50 | DH12: 229.87 | DI12: 103.91 | DJ12: 20.621 | DK12: 0.8633 | DL12: 13.387 | DM12: 23.731 | DN12: 752.2 | DO12: 17.828 | DP12: -3.5641026 | DQ12: 86.455555 | DT12: 100 | DU12: 277 | DV12: 60 | DW12: 276.89 | DX12: 99.09 | DY12: 20.779 | DZ12: 0.7574 | EA12: 18.813 | EB12: 23.744 | EC12: 753.5 | ED12: 17.871 | EE12: -3.3974359 | EF12: 86.005101
B13: 90 | C13: 120 | D13: 60 | E13: 119.88 | F13: 341.68 | G13: 40.601 | H13: 0.9913 | I13: 4.215 | J13: 47.762 | K13: 755 | L13: 36.029 | M13: -3.2051282 | N13: 88.739194 | Q13: 90 | R13: 230 | S13: 50 | T13: 229.81 | U13: 183.66 | V13: 40.221 | W13: 0.953 | X13: 6.714 | Y13: 47.671 | Z13: 754.6 | AA13: 35.934 | AB13: -3.2564103 | AC13: 89.341389 | AF13: 90 | AG13: 277 | AH13: 50 | AI13: 276.81 | AJ13: 158.19 | AK13: 40.242 | AL13: 0.919 | AM13: 9.117 | AN13: 47.609 | AO13: 754.4 | AP13: 35.88 | AQ13: -3.2820513 | AR13: 89.160579 | AV13: 90 | AW13: 120 | AX13: 60 | AY13: 119.89 | AZ13: 259.36 | BA13: 30.687 | BB13: 0.987 | BC13: 4.581 | BD13: 36.002 | BE13: 754.1 | BF13: 27.122 | BG13: -3.3205128 | BH13: 88.382703 | BK13: 90 | BL13: 230 | BM13: 50 | BN13: 229.85 | BO13: 143.65 | BP13: 30.619 | BQ13: 0.9274 | BR13: 8.652 | BS13: 35.997 | BT13: 753.9 | BU13: 27.111 | BV13: -3.3461538 | BW13: 88.543061 | BZ13: 90 | CA13: 277 | CB13: 60 | CC13: 276.86 | CD13: 130.14 | CE13: 30.739 | CF13: 0.8531 | CG13: 11.831 | CH13: 35.988 | CI13: 754.3 | CJ13: 27.119 | CK13: -3.2948718 | CL13: 88.22343 | CP13: 90 | CQ13: 120 | CR13: 60 | CS13: 119.82 | CT13: 175.97 | CU13: 20.518 | CV13: 0.9732 | CW13: 5.597 | CX13: 23.721 | CY13: 753.1 | CZ13: 17.844 | DA13: -3.4487179 | DB13: 86.967541 | DE13: 90 | DF13: 230 | DG13: 50 | DH13: 229.87 | DI13: 103.88 | DJ13: 20.614 | DK13: 0.8632 | DL13: 13.247 | DM13: 23.729 | DN13: 752.1 | DO13: 17.826 | DP13: -3.5769231 | DQ13: 86.475211 | DT13: 90 | DU13: 277 | DV13: 60 | DW13: 276.89 | DX13: 99.07 | DY13: 20.773 | DZ13: 0.7572 | EA13: 18.824 | EB13: 23.741 | EC13: 753.4 | ED13: 17.867 | EE13: -3.4102564 | EF13: 86.010687
B14: 80 | C14: 120 | D14: 60 | E14: 119.88 | F14: 341.52 | G14: 40.587 | H14: 0.9913 | I14: 4.028 | J14: 47.749 | K14: 755 | L14: 36.02 | M14: -3.2051282 | N14: 88.747629 | Q14: 80 | R14: 230 | S14: 50 | T14: 229.81 | U14: 183.56 | V14: 40.2 | W14: 0.9529 | X14: 6.798 | Y14: 47.66 | Z14: 754.5 | AA14: 35.924 | AB14: -3.2692308 | AC14: 89.363184 | AF14: 80 | AG14: 277 | AH14: 50 | AI14: 276.81 | AJ14: 158.11 | AK14: 40.217 | AL14: 0.919 | AM14: 8.803 | AN14: 47.598 | AO14: 754.2 | AP14: 35.866 | AQ14: -3.3076923 | AR14: 89.181192 | AV14: 80 | AW14: 120 | AX14: 60 | AY14: 119.89 | AZ14: 259.23 | BA14: 30.672 | BB14: 0.987 | BC14: 4.574 | BD14: 35.995 | BE14: 753.9 | BF14: 27.111 | BG14: -3.3461538 | BH14: 88.390063 | BK14: 80 | BL14: 230 | BM14: 50 | BN14: 229.85 | BO14: 143.61 | BP14: 30.613 | BQ14: 0.9274 | BR14: 8.66 | BS14: 35.991 | BT14: 753.9 | BU14: 27.108 | BV14: -3.3461538 | BW14: 88.550616 | BZ14: 80 | CA14: 277 | CB14: 60 | CC14: 276.86 | CD14: 130.09 | CE14: 30.724 | CF14: 0.853 | CG14: 11.903 | CH14: 35.981 | CI14: 754.3 | CJ14: 27.114 | CK14: -3.2948718 | CL14: 88.250228 | CP14: 80 | CQ14: 120 | CR14: 60 | CS14: 119.81 | CT14: 175.91 | CU14: 20.512 | CV14: 0.9732 | CW14: 5.628 | CX14: 23.717 | CY14: 753 | CZ14: 17.84 | DA14: -3.4615385 | DB14: 86.973479 | DE14: 80 | DF14: 230 | DG14: 50 | DH14: 229.88 | DI14: 103.88 | DJ14: 20.614 | DK14: 0.8632 | DL14: 12.891 | DM14: 23.728 | DN14: 752.1 | DO14: 17.826 | DP14: -3.5769231 | DQ14: 86.475211 | DT14: 80 | DU14: 277 | DV14: 60 | DW14: 276.89 | DX14: 99.05 | DY14: 20.768 | DZ14: 0.7572 | EA14: 17.88 | EB14: 23.738 | EC14: 753.5 | ED14: 17.864 | EE14: -3.3974359 | EF14: 86.016949
B15: 70 | C15: 120 | D15: 60 | E15: 119.88 | F15: 295.81 | G15: 35.124 | H15: 0.9905 | I15: 4.036 | J15: 47.237 | K15: 661.5 | L15: 31.213 | M15: -15.192308 | N15: 88.865163 | Q15: 70 | R15: 230 | S15: 50 | T15: 229.82 | U15: 161.22 | V15: 34.923 | W15: 0.9426 | X15: 7.469 | Y15: 47.155 | Z15: 661.6 | AA15: 31.167 | AB15: -15.179487 | AC15: 89.24491 | AF15: 70 | AG15: 277 | AH15: 50 | AI15: 276.83 | AJ15: 140.05 | AK15: 34.954 | AL15: 0.9016 | AM15: 9.332 | AN15: 47.097 | AO15: 661.1 | AP15: 31.104 | AQ15: -15.24359 | AR15: 88.985524 | AV15: 70 | AW15: 120 | AX15: 60 | AY15: 119.9 | AZ15: 225.73 | BA15: 26.625 | BB15: 0.9838 | BC15: 4.089 | BD15: 35.603 | BE15: 661.7 | BF15: 23.537 | BG15: -15.166667 | BH15: 88.401878 | BK15: 70 | BL15: 230 | BM15: 50 | BN15: 229.86 | BO15: 126.92 | BP15: 26.59 | BQ15: 0.9115 | BR15: 8.624 | BS15: 35.597 | BT15: 661.2 | BU15: 23.512 | BV15: -15.230769 | BW15: 88.42422 | BZ15: 70 | CA15: 277 | CB15: 60 | CC15: 276.87 | CD15: 116.94 | CE15: 26.702 | CF15: 0.8247 | CG15: 14.075 | CH15: 35.588 | CI15: 661.3 | CJ15: 23.512 | CK15: -15.217949 | CL15: 88.053329 | CP15: 70 | CQ15: 120 | CR15: 60 | CS15: 119.83 | CT15: 153.62 | CU15: 17.807 | CV15: 0.9673 | CW15: 5.541 | CX15: 23.494 | CY15: 660.3 | CZ15: 15.497 | DA15: -15.346154 | DB15: 87.027573 | DE15: 70 | DF15: 230 | DG15: 50 | DH15: 229.89 | DI15: 93.11 | DJ15: 17.947 | DK15: 0.8384 | DL15: 13.679 | DM15: 23.507 | DN15: 660 | DO15: 15.495 | DP15: -15.384615 | DQ15: 86.337549 | DT15: 70 | DU15: 277 | DV15: 60 | DW15: 276.9 | DX15: 90.57 | DY15: 18.08 | DZ15: 0.721 | EA15: 19.612 | EB15: 23.514 | EC15: 660.8 | ED15: 15.519 | EE15: -15.282051 | EF15: 85.835177
B16: 60 | C16: 120 | D16: 60 | E16: 119.89 | F16: 238.23 | G16: 28.165 | H16: 0.9862 | I16: 4.134 | J16: 46.522 | K16: 537.6 | L16: 24.983 | M16: -31.076923 | N16: 88.70229 | Q16: 60 | R16: 230 | S16: 50 | T16: 229.84 | U16: 132.02 | V16: 27.968 | W16: 0.9217 | X16: 8.121 | Y16: 46.439 | Z16: 536.5 | AA16: 24.887 | AB16: -31.217949 | AC16: 88.983839 | AF16: 60 | AG16: 277 | AH16: 50 | AI16: 276.84 | AJ16: 116.79 | AK16: 28.052 | AL16: 0.8675 | AM16: 11.406 | AN16: 46.389 | AO16: 536.8 | AP16: 24.873 | AQ16: -31.179487 | AR16: 88.667475 | AV16: 60 | AW16: 120 | AX16: 60 | AY16: 119.9 | AZ16: 181.92 | BA16: 21.306 | BB16: 0.9769 | BC16: 4.169 | BD16: 35.046 | BE16: 537.8 | BF16: 18.829 | BG16: -31.051282 | BH16: 88.374167 | BK16: 60 | BL16: 230 | BM16: 50 | BN16: 229.87 | BO16: 105.56 | BP16: 21.361 | BQ16: 0.8803 | BR16: 10.373 | BS16: 35.041 | BT16: 537.6 | BU16: 18.82 | BV16: -31.076923 | BW16: 88.104489 | BZ16: 60 | CA16: 277 | CB16: 60 | CC16: 276.88 | CD16: 100.39 | CE16: 21.485 | CF16: 0.7731 | CG16: 16.688 | CH16: 35.037 | CI16: 538 | CJ16: 18.831 | CK16: -31.025641 | CL16: 87.647196 | CP16: 60 | CQ16: 120 | CR16: 60 | CS16: 119.85 | CT16: 125.13 | CU16: 14.304 | CV16: 0.9538 | CW16: 5.676 | CX16: 23.183 | CY16: 537.5 | CZ16: 12.447 | DA16: -31.089744 | DB16: 87.017617 | DE16: 60 | DF16: 230 | DG16: 50 | DH16: 229.89 | DI16: 79.53 | DJ16: 14.462 | DK16: 0.791 | DL16: 16.207 | DM16: 23.196 | DN16: 537 | DO16: 12.442 | DP16: -31.153846 | DQ16: 86.032361 | DT16: 60 | DU16: 277 | DV16: 60 | DW16: 276.91 | DX16: 79.73 | DY16: 14.588 | DZ16: 0.6608 | EA16: 23.548 | EB16: 23.205 | EC16: 537.8 | ED16: 12.466 | EE16: -31.051282 | EF16: 85.453798
B17: 50 | C17: 120 | D17: 60 | E17: 119.9 | F17: 181.85 | G17: 21.335 | H17: 0.9785 | I17: 4.548 | J17: 45.748 | K17: 413.2 | L17: 18.884 | M17: -47.025641 | N17: 88.511835 | Q17: 50 | R17: 230 | S17: 50 | T17: 229.86 | U17: 104.81 | V17: 21.274 | W17: 0.8831 | X17: 9.355 | Y17: 45.671 | Z17: 412.5 | AA17: 18.819 | AB17: -47.115385 | AC17: 88.460092 | AF17: 50 | AG17: 277 | AH17: 50 | AI17: 276.86 | AJ17: 94.98 | AK17: 21.349 | AL17: 0.812 | AM17: 13.976 | AN17: 45.624 | AO17: 412.5 | AP17: 18.797 | AQ17: -47.115385 | AR17: 88.046279 | AV17: 50 | AW17: 120 | AX17: 60 | AY17: 119.84 | AZ17: 139.13 | BA17: 16.088 | BB17: 0.9649 | BC17: 5.597 | BD17: 34.44 | BE17: 412.6 | BF17: 14.194 | BG17: -47.102564 | BH17: 88.22725 | BK17: 50 | BL17: 230 | BM17: 50 | BN17: 229.89 | BO17: 85.16 | BP17: 16.18 | BQ17: 0.8266 | BR17: 13.023 | BS17: 34.431 | BT17: 412.2 | BU17: 14.174 | BV17: -47.153846 | BW17: 87.601978 | BZ17: 50 | CA17: 277 | CB17: 60 | CC17: 276.89 | CD17: 84.59 | CE17: 16.333 | CF17: 0.6973 | CG17: 19.482 | CH17: 34.431 | CI17: 413.1 | CJ17: 14.209 | CK17: -47.038462 | CL17: 86.995653 | CP17: 50 | CQ17: 120 | CR17: 60 | CS17: 119.87 | CT17: 97.75 | CU17: 10.868 | CV17: 0.9276 | CW17: 8.416 | CX17: 22.848 | CY17: 413.2 | CZ17: 9.43 | DA17: -47.025641 | DB17: 86.768495 | DE17: 50 | DF17: 230 | DG17: 50 | DH17: 229.9 | DI17: 66.67 | DJ17: 11.033 | DK17: 0.7199 | DL17: 19.698 | DM17: 22.861 | DN17: 413.2 | DO17: 9.435 | DP17: -47.025641 | DQ17: 85.516179 | DT17: 50 | DU17: 277 | DV17: 60 | DW17: 276.91 | DX17: 69.21 | DY17: 11.137 | DZ17: 0.5811 | EA17: 27.19 | EB17: 22.867 | EC17: 413.2 | ED17: 9.439 | EE17: -47.025641 | EF17: 84.753524
B18: 40 | C18: 120 | D18: 60 | E18: 119.85 | F18: 128.21 | G18: 14.741 | H18: 0.9593 | I18: 4.342 | J18: 44.89 | K18: 288.78 | L18: 12.95 | M18: -62.976923 | N18: 87.850214 | Q18: 40 | R18: 230 | S18: 50 | T18: 229.88 | U18: 79.41 | V18: 14.754 | W18: 0.8083 | X18: 12.816 | Y18: 44.817 | Z18: 288.17 | AA18: 12.901 | AB18: -63.055128 | AC18: 87.440694 | AF18: 40 | AG18: 277 | AH18: 50 | AI18: 276.87 | AJ18: 75.01 | AK18: 14.883 | AL18: 0.7165 | AM18: 18.903 | AN18: 44.78 | AO18: 288.7 | AP18: 12.914 | AQ18: -62.987179 | AR18: 86.77014 | AV18: 40 | AW18: 120 | AX18: 60 | AY18: 119.87 | AZ18: 99.13 | BA18: 11.092 | BB18: 0.9336 | BC18: 5.508 | BD18: 33.77 | BE18: 288.01 | BF18: 9.715 | BG18: -63.075641 | BH18: 87.585647 | BK18: 40 | BL18: 230 | BM18: 50 | BN18: 229.9 | BO18: 66.79 | BP18: 11.238 | BQ18: 0.7319 | BR18: 16.65 | BS18: 33.767 | BT18: 288.28 | BU18: 9.723 | BV18: -63.041026 | BW18: 86.518954 | BZ18: 40 | CA18: 277 | CB18: 60 | CC18: 276.91 | CD18: 70.05 | CE18: 11.382 | CF18: 0.5868 | CG18: 25.057 | CH18: 33.768 | CI18: 289.18 | CJ18: 9.756 | CK18: -62.925641 | CL18: 85.714286 | CP18: 40 | CQ18: 120 | CR18: 60 | CS18: 119.89 | CT18: 71.95 | CU18: 7.517 | CV18: 0.8714 | CW18: 11.233 | CX18: 22.472 | CY18: 288.71 | CZ18: 6.481 | DA18: -62.985897 | DB18: 86.217906 | DE18: 40 | DF18: 230 | DG18: 50 | DH18: 229.91 | DI18: 54.61 | DJ18: 7.673 | DK18: 0.6111 | DL18: 25.64 | DM18: 22.483 | DN18: 288.35 | DO18: 6.475 | DP18: -63.032051 | DQ18: 84.386811 | DT18: 40 | DU18: 277 | DV18: 60 | DW18: 276.92 | DX18: 59.26 | DY18: 7.801 | DZ18: 0.4754 | EA18: 31.075 | EB18: 22.493 | EC18: 289.11 | ED18: 6.496 | EE18: -62.934615 | EF18: 83.271375
B19: 30 | C19: 120 | D19: 60 | E19: 119.88 | F19: 77.68 | G19: 8.333 | H19: 0.8951 | I19: 6.974 | J19: 43.876 | K19: 164.07 | L19: 7.189 | M19: -78.965385 | N19: 86.271451 | Q19: 30 | R19: 230 | S19: 50 | T19: 229.9 | U19: 56.8 | V19: 8.441 | W19: 0.6464 | X19: 20.502 | Y19: 43.815 | Z19: 164.04 | AA19: 7.178 | AB19: -78.969231 | AC19: 85.037318 | AF19: 30 | AG19: 277 | AH19: 50 | AI19: 276.89 | AJ19: 56.88 | AK19: 8.559 | AL19: 0.5435 | AM19: 26.378 | AN19: 43.784 | AO19: 164.5 | AP19: 7.195 | AQ19: -78.910256 | AR19: 84.063559 | AV19: 30 | AW19: 120 | AX19: 60 | AY19: 119.89 | AZ19: 62.5 | BA19: 6.272 | BB19: 0.8368 | BC19: 9.374 | BD19: 32.984 | BE19: 163.76 | BF19: 5.394 | BG19: -79.005128 | BH19: 86.001276 | BK19: 30 | BL19: 230 | BM19: 50 | BN19: 229.91 | BO19: 50.36 | BP19: 6.446 | BQ19: 0.5566 | BR19: 26.35 | BS19: 32.986 | BT19: 164.3 | BU19: 5.413 | BV19: -78.935897 | BW19: 83.974558 | BZ19: 30 | CA19: 277 | CB19: 60 | CC19: 276.92 | CD19: 56.62 | CE19: 6.55 | CF19: 0.4177 | CG19: 33.701 | CH19: 32.981 | CI19: 164.59 | CJ19: 5.423 | CK19: -78.898718 | CL19: 82.793893 | CP19: 30 | CQ19: 120 | CR19: 60 | CS19: 119.91 | CT19: 49.13 | CU19: 4.267 | CV19: 0.7244 | CW19: 15.453 | CX19: 22.024 | CY19: 164.24 | CZ19: 3.612 | DA19: -78.94359 | DB19: 84.649637 | DE19: 30 | DF19: 230 | DG19: 50 | DH19: 229.92 | DI19: 44.32 | DJ19: 4.436 | DK19: 0.4353 | DL19: 32.476 | DM19: 22.036 | DN19: 164.32 | DO19: 3.617 | DP19: -78.933333 | DQ19: 81.537421 | DT19: 30 | DU19: 277 | DV19: 60 | DW19: 276.93 | DX19: 49 | DY19: 4.564 | DZ19: 0.3364 | EA19: 34.685 | EB19: 22.044 | EC19: 164.7 | ED19: 3.627 | EE19: -78.884615 | EF19: 79.469763
B20: 20 | C20: 120 | D20: 60 | E20: 119.92 | F20: 49.3 | G20: 1.913 | H20: 0.3228 | I20: 55.03 | J20: 42.262 | K20: 34.15 | L20: 1.4431 | M20: -95.621795 | N20: 75.436487 | Q20: 20 | R20: 230 | S20: 50 | T20: 229.92 | U20: 35.31 | V20: 2.045 | W20: 0.2519 | X20: 39.573 | Y20: 42.206 | Z20: 34.33 | AA20: 1.4488 | AB20: -95.598718 | AC20: 70.845966 | AF20: 20 | AG20: 277 | AH20: 50 | AI20: 276.9 | AJ20: 35.86 | AK20: 2.105 | AL20: 0.212 | AM20: 32.771 | AN20: 42.172 | AO20: 34.4 | AP20: 1.4505 | AQ20: -95.589744 | AR20: 68.907363 | AV20: 20 | AW20: 120 | AX20: 60 | AY20: 119.92 | AZ20: 41.75 | BA20: 1.535 | BB20: 0.3069 | BC20: 50.052 | BD20: 31.766 | BE20: 36.45 | BF20: 1.1578 | BG20: -95.326923 | BH20: 75.42671 | BK20: 20 | BL20: 230 | BM20: 50 | BN20: 229.92 | BO20: 32.88 | BP20: 1.674 | BQ20: 0.2214 | BR20: 34.629 | BS20: 31.768 | BT20: 36.6 | BU20: 1.1625 | BV20: -95.307692 | BW20: 69.444444 | BZ20: 20 | CA20: 277 | CB20: 60 | CC20: 276.93 | CD20: 37.79 | CE20: 1.688 | CF20: 0.1613 | CG20: 27.327 | CH20: 31.761 | CI20: 36.45 | CJ20: 1.1576 | CK20: -95.326923 | CL20: 68.578199 | CP20: 20 | CQ20: 120 | CR20: 60 | CS20: 119.92 | CT20: 33.98 | CU20: 1.125 | CV20: 0.276 | CW20: 46.248 | CX20: 21.314 | CY20: 38.73 | CZ20: 0.8253 | DA20: -95.034615 | DB20: 73.36 | DE20: 20 | DF20: 230 | DG20: 50 | DH20: 229.93 | DI20: 30.67 | DJ20: 1.207 | DK20: 0.1711 | DL20: 30.434 | DM20: 21.323 | DN20: 38.52 | DO20: 0.8212 | DP20: -95.061538 | DQ20: 68.036454 | DT20: 20 | DU20: 277 | DV20: 60 | DW20: 276.93 | DX20: 36.25 | DY20: 1.237 | DZ20: 0.1232 | EA20: 27.192 | EB20: 21.33 | EC20: 38.69 | ED20: 0.8252 | EE20: -95.039744 | EF20: 66.709782
B21: 10 | C21: 120 | D21: 60 | E21: 119.92 | F21: 26.979 | G21: 0.5282 | H21: 0.1632 | I21: 47.559 | J21: 41.238 | K21: 7.007 | L21: 0.289 | M21: -99.101667 | N21: 54.714123 | Q21: 10 | R21: 230 | S21: 50 | T21: 229.92 | U21: 28.123 | V21: 0.544 | W21: 0.0842 | X21: 19.636 | Y21: 41.177 | Z21: 7.019 | AA21: 0.289 | AB21: -99.100128 | AC21: 53.125 | AF21: 10 | AG21: 277 | AH21: 50 | AI21: 276.9 | AJ21: 30.51 | AK21: 0.561 | AL21: 0.0665 | AM21: 22.558 | AN21: 41.125 | AO21: 6.875 | AP21: 0.2827 | AQ21: -99.11859 | AR21: 50.392157 | AV21: 10 | AW21: 120 | AX21: 60 | AY21: 119.93 | AZ21: 26.272 | BA21: 0.4258 | BB21: 0.1352 | BC21: 44.391 | BD21: 30.961 | BE21: 7.54 | BF21: 0.2334 | BG21: -99.033333 | BH21: 54.814467 | BK21: 10 | BL21: 230 | BM21: 50 | BN21: 229.93 | BO21: 27.876 | BP21: 0.444 | BQ21: 0.0693 | BR21: 23.514 | BS21: 30.951 | BT21: 7.457 | BU21: 0.2308 | BV21: -99.043974 | BW21: 51.981982 | BZ21: 10 | CA21: 277 | CB21: 60 | CC21: 276.93 | CD21: 34.12 | CE21: 0.471 | CF21: 0.0499 | CG21: 12.189 | CH21: 30.948 | CI21: 7.455 | CJ21: 0.23071 | CK21: -99.044231 | CL21: 48.983015 | CP21: 10 | CQ21: 120 | CR21: 60 | CS21: 119.92 | CT21: 31.07 | CU21: 0.927 | CV21: 0.2489 | CW21: 47.77 | CX21: 21.231 | CY21: 31.05 | CZ21: 0.6592 | DA21: -96.019231 | DB21: 71.111111 | DE21: 10 | DF21: 230 | DG21: 50 | DH21: 229.93 | DI21: 29.766 | DJ21: 0.99 | DK21: 0.1447 | DL21: 32.616 | DM21: 21.242 | DN21: 30.99 | DO21: 0.6584 | DP21: -96.026923 | DQ21: 66.505051 | DT21: 10 | DU21: 277 | DV21: 60 | DW21: 276.94 | DX21: 35.55 | DY21: 1.013 | DZ21: 0.1029 | EA21: 25.533 | EB21: 21.246 | EC21: 30.92 | ED21: 0.6568 | EE21: -96.035897 | EF21: 64.837117
